<?xml version="1.0" ?>
<!-- =================================================================================== -->
<!-- |    This document was autogenerated by xacro from primo_sim.xacro                | -->
<!-- |    EDITING THIS FILE BY HAND IS NOT RECOMMENDED                                 | -->
<!-- =================================================================================== -->
<robot name="primo" xmlns:xacro="http://www.ros.org/wiki/xacro">
  <gazebo>
    <plugin filename="libgazebo_ros_control.so" name="gazebo_ros_control">
      <robotNamespace>/</robotNamespace>
    </plugin>
  </gazebo>
  <gazebo>
    <plugin filename="libgazebo_ros_diff_drive.so" name="differential_drive_controller">
      <legacyMode>false</legacyMode>
      <alwaysOn>true</alwaysOn>
      <updateRate>10</updateRate>
      <leftJoint>left_wheel_joint</leftJoint>
      <rightJoint>right_wheel_joint</rightJoint>
      <wheelSeparation>0.4</wheelSeparation>
      <wheelDiameter>0.2</wheelDiameter>
      <torque>10</torque>
      <commandTopic>cmd_vel</commandTopic>
      <odometryTopic>odom</odometryTopic>
      <odometryFrame>odom</odometryFrame>
      <robotBaseFrame>chassis</robotBaseFrame>
    </plugin>
  </gazebo>
  <gazebo reference="link_seecam1">
    <material>Gazebo/Green</material>
    <sensor name="seecam1" type="camera">
      <update_rate>30.0</update_rate>
      <camera name="head">
        <horizontal_fov>1.3962634</horizontal_fov>
        <image>
          <width>800</width>
          <height>600</height>
          <format>R8G8B8</format>
        </image>
        <clip>
          <near>0.02</near>
          <far>300</far>
        </clip>
      </camera>
      <plugin filename="libgazebo_ros_camera.so" name="camera_controller">
        <alwaysOn>true</alwaysOn>
        <updateRate>0.0</updateRate>
        <cameraName>primo/camera1</cameraName>
        <imageTopicName>image_raw</imageTopicName>
        <cameraInfoTopicName>camera_info</cameraInfoTopicName>
        <frameName>link_seecam1</frameName>
        <hackBaseline>0.07</hackBaseline>
        <distortionK1>0.0</distortionK1>
        <distortionK2>0.0</distortionK2>
        <distortionK3>0.0</distortionK3>
        <distortionT1>0.0</distortionT1>
        <distortionT2>0.0</distortionT2>
      </plugin>
    </sensor>
  </gazebo>
  <link name="base_link">
    <visual>
      <geometry>
        <mesh filename="package://primo_description/meshes/r1_primo_sim.stl"/>
      </geometry>
    </visual>
    <collision name="collision">
      <origin xyz="0 0 .4"/>
      <geometry>
        <box size=".94 .66 .5"/>
      </geometry>
    </collision>
    <inertial>
      <mass value="15.0"/>
      <origin rpy=" 0 0 0" xyz="0.0 0 0.001"/>
      <inertia ixx="0.1" ixy="0" ixz="0" iyy="0.1" iyz="0" izz="0.1"/>
    </inertial>
  </link>
  <link name="left_wheel">
    <visual>
      <geometry>
        <mesh filename="package://primo_description/meshes/r1_wheel.stl"/>
      </geometry>
    </visual>
    <origin rpy="0 0 0" xyz="0 0 0"/>
    <collision name="collision">
      <!-- <origin xyz="0 0 0" rpy="0 1.5707 1.5707"/> -->
      <origin rpy="0 0 0" xyz="0 0 0"/>
      <geometry>
        <cylinder length="0.064" radius="0.1145"/>
      </geometry>
    </collision>
    <inertial>
      <origin rpy="0 1.5707 1.5707" xyz="0 0 0"/>
      <mass value="5"/>
      <inertia ixx=".1" ixy="0.0" ixz="0.0" iyy=".1" iyz="0.0" izz=".1"/>
    </inertial>
  </link>
  <joint name="left_wheel_joint" type="continuous">
    <parent link="base_link"/>
    <child link="left_wheel"/>
    <origin rpy="0 0 0" xyz="0 0.3175 0.1510"/>
    <axis rpy="0 0 0" xyz="0 1 0"/>
  </joint>
  <!-- Gazebo wheel reference -->
  <gazebo reference="left_wheel">
    <mu1 value="200.0"/>
    <mu2 value="100.0"/>
    <kp value="10000000.0"/>
    <kd value="1.0"/>
    <material>Gazebo/Black</material>
  </gazebo>
  <transmission name="left_wheel">
    <type>transmission_interface/SimpleTransmission</type>
    <actuator name="left_wheel_motor">
      <mechanicalReduction>1</mechanicalReduction>
    </actuator>
    <joint name="left_wheel_joint">
      <hardwareInterface>hardware_interface/VelocityJointInterface</hardwareInterface>
    </joint>
  </transmission>
  <link name="right_wheel">
    <visual>
      <geometry>
        <mesh filename="package://primo_description/meshes/r1_wheel.stl"/>
      </geometry>
    </visual>
    <origin rpy="0 0 0" xyz="0 0 0"/>
    <collision name="collision">
      <!-- <origin xyz="0 0 0" rpy="0 1.5707 1.5707"/> -->
      <origin rpy="0 0 0" xyz="0 0 0"/>
      <geometry>
        <cylinder length="0.064" radius="0.1145"/>
      </geometry>
    </collision>
    <inertial>
      <origin rpy="0 1.5707 1.5707" xyz="0 0 0"/>
      <mass value="5"/>
      <inertia ixx=".1" ixy="0.0" ixz="0.0" iyy=".1" iyz="0.0" izz=".1"/>
    </inertial>
  </link>
  <joint name="right_wheel_joint" type="continuous">
    <parent link="base_link"/>
    <child link="right_wheel"/>
    <origin rpy="0 0 0" xyz="0 -0.3175 0.1510"/>
    <axis rpy="0 0 0" xyz="0 1 0"/>
  </joint>
  <!-- Gazebo wheel reference -->
  <gazebo reference="right_wheel">
    <mu1 value="200.0"/>
    <mu2 value="100.0"/>
    <kp value="10000000.0"/>
    <kd value="1.0"/>
    <material>Gazebo/Black</material>
  </gazebo>
  <transmission name="right_wheel">
    <type>transmission_interface/SimpleTransmission</type>
    <actuator name="right_wheel_motor">
      <mechanicalReduction>1</mechanicalReduction>
    </actuator>
    <joint name="right_wheel_joint">
      <hardwareInterface>hardware_interface/VelocityJointInterface</hardwareInterface>
    </joint>
  </transmission>
  <link name="tail_wheel">
    <visual>
      <geometry>
        <cylinder length="0.064" radius="0.0795"/>
      </geometry>
    </visual>
    <origin rpy="0 0 0" xyz="0 0 0"/>
    <collision name="collision">
      <origin rpy="0 0 0" xyz="0 0 0"/>
      <geometry>
        <cylinder length="0.064" radius="0.0795"/>
      </geometry>
    </collision>
    <inertial>
      <origin rpy="0 1.5707 1.5707" xyz="0 0 0"/>
      <mass value="1"/>
      <inertia ixx=".1" ixy="0.0" ixz="0.0" iyy=".1" iyz="0.0" izz=".1"/>
    </inertial>
  </link>
  <joint name="wheel_to_block" type="continuous">
    <parent link="tail_wheel_block"/>
    <child link="tail_wheel"/>
    <origin rpy="1.5707 0 0" xyz="-.05 0 -0.0795"/>
    <axis rpy="0 0 0" xyz="0 0 1"/>
  </joint>
  <transmission name="tail_wheel_spin_trans">
    <type>transmission_interface/SimpleTransmission</type>
    <actuator name="tail_wheel_spin_motor">
      <mechanicalReduction>1</mechanicalReduction>
    </actuator>
    <joint name="wheel_to_block">
      <hardwareInterface>hardware_interface/PositionJointInterface</hardwareInterface>
    </joint>
  </transmission>
  <link name="tail_wheel_block">
    <visual>
      <geometry>
        <box size=".1 .1 .1"/>
      </geometry>
    </visual>
    <origin rpy="0 0 0" xyz="0 0 0"/>
    <collision name="collision">
      <origin rpy="0 1.5707 1.5707" xyz="0 0 0"/>
      <geometry>
        <box size=".1 .1 .1"/>
      </geometry>
    </collision>
    <inertial>
      <origin rpy="0 1.5707 1.5707" xyz="0 0 0"/>
      <mass value="1"/>
      <inertia ixx=".1" ixy="0.0" ixz="0.0" iyy=".1" iyz="0.0" izz=".1"/>
    </inertial>
  </link>
  <joint name="wheel_block" type="continuous">
    <parent link="base_link"/>
    <child link="tail_wheel_block"/>
    <origin rpy="0 0 0" xyz="-0.730 0 0.180"/>
    <axis rpy="0 0 0" xyz="0 0 1"/>
  </joint>
  <transmission name="tail_wheel_swivel_trans">
    <type>transmission_interface/SimpleTransmission</type>
    <actuator name="tail_wheel_swivel_motor">
      <mechanicalReduction>1</mechanicalReduction>
    </actuator>
    <joint name="wheel_block">
      <hardwareInterface>hardware_interface/PositionJointInterface</hardwareInterface>
    </joint>
  </transmission>
  <link name="stereo0_link">
    <!-- this name is required for the point cloud -->
    <collision>
      <origin rpy="0 0 0" xyz="0 0 0"/>
      <geometry>
        <box size="0.05 0.05 0.05"/>
      </geometry>
    </collision>
    <visual>
      <origin rpy="0 0 0" xyz="0 0 0"/>
      <geometry>
        <box size="0.05 0.05 0.05"/>
      </geometry>
      <material name="red"/>
    </visual>
    <inertial>
      <mass value="0.1"/>
      <origin rpy="0 0 0" xyz="0 0 0"/>
      <box_inertia m="0.1" x="0.05" y="0.05" z="0.05"/>
      <inertia ixx="1e-6" ixy="0" ixz="0" iyy="1e-6" iyz="0" izz="1e-6"/>
    </inertial>
  </link>
  <joint name="stereo0_joint" type="fixed">
    <!-- origin xyz=".1 -.10 1.143" rpy="-1.570796 0 -1.570796"/-->
    <origin rpy="-2.48 0 -1.570796" xyz=".085 .210 1.765"/>
    <parent link="base_link"/>
    <child link="stereo0_link"/>
  </joint>
</robot>

