<?xml version="1.0"?>
<robot xmlns:xacro="http://www.ros.org/wiki/xacro">

    <!-- parameters -->
    <xacro:property name="seecamSize" value="0.05"/>
    <xacro:property name="seecamMass" value="0.1"/>
    <xacro:property name="camSize" value="0.05"/>
    <xacro:property name="camMass" value="0.1"/>

    <material name="red">
        <color rgba="1 0 0 1"/>
    </material>
    <material name="green">
        <color rgba="0 1 0 1"/>
    </material>
    <material name="blue">
        <color rgba="0 0 1 1"/>
    </material>
    <material name="white">
        <color rgba="1 1 1 1"/>
    </material>

    <xacro:macro name="m_align_link" params="name color shape">
        <link name="${type}${num}_${name}_link">
            <visual>
                <xacro:if value="${shape == 'box'}">
                    <geometry>
                        <box size="0.1 0.1 0.1"/>
                    </geometry>
                </xacro:if>
                <xacro:if value="${shape == 'cylinder'}">
                    <geometry>
                        <cylinder length="0.2" radius ="0.02"/>
                    </geometry>
                </xacro:if>
                <material name="${color}"/>
            </visual>
        </link>
    </xacro:macro>

    <!-- Camera align system macro. 
         This takes in a camera type, camera number, and its last 
         known x,y,z,roll,pitch,yaw transform. It then builds an 
         alignemnt tree with the last known transform as the starting 
         point. -->
    <xacro:macro name="m_camera_align" params="type num x y z roll pitch yaw">

        <!-- Final cam link -->
        <link name="${type}${num}_link">
            <collision>
                <origin xyz="0 0 0" rpy="0 0 0"/>
                <geometry>
                    <box size="${camSize} ${camSize} ${camSize}"/>
                </geometry>
            </collision>
            <visual>
                <origin xyz="0 0 0" rpy="0 0 0"/>
                <geometry>
                    <box size="${camSize} ${camSize} ${camSize}"/>
                </geometry>
                <material name="red"/>
            </visual>
            <inertial>
                <mass value="${camMass}"/>
                <origin xyz="0 0 0" rpy="0 0 0"/>
                <inertia 
                    ixx="1e-6" ixy="0" ixz="0" 
                    iyy="1e-6" iyz="0" 
                    izz="1e-6"/>
            </inertial>
        </link>

        <!-- Translation Base Link --> 
        <link name="${type}${num}_trans_link">
            <collision>
                <origin xyz="0 0 0" rpy="0 0 0"/>
                <geometry>
                    <box size="${camSize} ${camSize} ${camSize}"/>
                </geometry>
            </collision>
            <visual>
                <origin xyz="0 0 0" rpy="0 0 0"/>
                <geometry>
                    <box size="${camSize} ${camSize} ${camSize}"/>
                </geometry>
                <material name="red"/>
            </visual>
            <inertial>
                <mass value="${camMass}"/>
                <origin xyz="0 0 0" rpy="0 0 0"/>
                <inertia 
                    ixx="1e-6" ixy="0" ixz="0" 
                    iyy="1e-6" iyz="0" 
                    izz="1e-6"/>
            </inertial>
        </link>

        <!-- Rotary Base Link --> 
        <link name="${type}${num}_rotary_link">
            <collision>
                <origin xyz="0 0 0" rpy="0 0 0"/>
                <geometry>
                    <box size="${camSize} ${camSize} ${camSize}"/>
                </geometry>
            </collision>
            <visual>
                <origin xyz="0 0 0" rpy="0 0 0"/>
                <geometry>
                    <box size="${camSize} ${camSize} ${camSize}"/>
                </geometry>
                <material name="red"/>
            </visual>
            <inertial>
                <mass value="${camMass}"/>
                <origin xyz="0 0 0" rpy="0 0 0"/>
                <inertia 
                    ixx="1e-6" ixy="0" ixz="0" 
                    iyy="1e-6" iyz="0" 
                    izz="1e-6"/>
            </inertial>
        </link>


        <!-- Joint links -->
        <xacro:m_align_link name="x"      color="red"     shape="box"/>
        <xacro:m_align_link name="y"      color="green"   shape="box"/>
        <xacro:m_align_link name="z"      color="blue"    shape="box"/>
        <xacro:m_align_link name="roll"   color="red"     shape="cylinder"/>
        <xacro:m_align_link name="pitch"  color="green"   shape="cylinder"/>
        <xacro:m_align_link name="yaw"    color="blue"    shape="cylinder"/>

        <!-- Translation base joint -->
        <joint name="${type}${num}_trans_base_joint" type="fixed">
            <origin xyz="${x} ${y} ${z}" rpy="0 0 0"/>
            <axis xyz="0 0 0"/>
            <parent link="chassis_link"/>
            <child link="${type}${num}_trans_link"/>
        </joint>

        <!-- Translation Joints -->
        <joint name="${type}${num}_align_x_joint" type="prismatic">
            <origin xyz="0 0 0" rpy="0 0 0"/>
            <axis xyz="1 0 0"/>
            <parent link="chassis_link"/>
            <child link="${type}${num}_x_link"/>
            <limit effort="1000" lower="-2.5" upper="2.5" velocity="1000"/>
        </joint>

        <joint name="${type}${num}_align_y_joint" type="prismatic">
            <origin xyz="0 0 0" rpy="0 0 0"/>
            <axis xyz="0 1 0"/>
            <parent link="${type}${num}_x_link"/>
            <child link="${type}${num}_y_link"/>
            <limit effort="1000" lower="-2.5" upper="2.5" velocity="1000"/>
        </joint>

        <joint name="${type}${num}_align_z_joint" type="prismatic">
            <origin xyz="0 0 0" rpy="0 0 0"/>
            <axis xyz="0 0 1"/>
            <parent link="${type}${num}_y_link"/>
            <child link="${type}${num}_z_link"/>
            <limit effort="1000" lower="-2.5" upper="2.5" velocity="1000"/>
        </joint>

        <!-- Rotary base joint -->
        <joint name="${type}${num}_trans_base_joint" type="fixed">
            <origin xyz="0 0 0" rpy="${roll} ${pitch} ${yaw}"/>            
            <axis xyz="0 0 0"/>
            <parent link="${type}${num}_z_link"/>
            <child link="${type}${num}_rotary_link"/>
        </joint>

        <!-- Rotation Joints -->
        <joint name="${type}${num}_align_roll_joint" type="continuous">
            <origin xyz="0 0 0"/>
            <axis xyz="1 0 0"/>
            <parent link="${type}${num}_rotary_link"/>
            <child link="${type}${num}_roll_link"/>
        </joint>

        <joint name="${type}${num}_align_pitch_joint" type="continuous">
            <origin xyz="0 0 0"/>
            <axis xyz="0 1 0"/>
            <parent link="${type}${num}_roll_link"/>
            <child link="${type}${num}_pitch_link"/>
        </joint>

        <joint name="${type}${num}_align_yaw_joint" type="continuous">
            <origin xyz="0 0 0"/>
            <axis xyz="0 0 1"/>
            <parent link="${type}${num}_pitch_link"/>
            <child link="${type}${num}_yaw_link"/>
        </joint>

        <!-- Final connection -->
        <joint name="${type}${num}_align_con_joint" type="fixed">
            <origin xyz="0 0 0"/>
            <parent link="${type}${num}_yaw_link"/>
            <child link="${type}${num}_link"/>
        </joint>

        <!-- The corrected link for gazebo -->
        <link name="${type}${num}_corrected_link">
            <inertial>
                <mass value="0"/>
                <origin xyz="0 0 0" rpy="0 0 0"/>
                <inertia 
                    ixx="1e-6" ixy="0" ixz="0" 
                    iyy="1e-6" iyz="0" 
                    izz="1e-6"/>
            </inertial>
        </link>

        <joint name="${type}${num}_corrected_joint" type="fixed">
            <origin xyz="0 0 0" rpy="1.57079632679 -1.5707963267 0"/>
            <parent link="${type}${num}_link"/>
            <child link="${type}${num}_corrected_link"/>
        </joint>

    </xacro:macro>
</robot>
